Requirement already satisfied: pip in /root/.local/share/pypoetry/venv/lib/python3.9/site-packages (23.0.1)
Collecting pip
  Downloading pip-23.1.2-py3-none-any.whl (2.1 MB)
     ━━━━━━━━━━━━━━━━━━━━━━━━╸                1.3/2.1 MB 2.6 kB/s eta 0:05:04
ERROR: Exception:
Traceback (most recent call last):
  File "/root/.local/share/pypoetry/venv/lib/python3.9/site-packages/pip/_vendor/urllib3/response.py", line 438, in _error_catcher
    yield
  File "/root/.local/share/pypoetry/venv/lib/python3.9/site-packages/pip/_vendor/urllib3/response.py", line 561, in read
    data = self._fp_read(amt) if not fp_closed else b""
  File "/root/.local/share/pypoetry/venv/lib/python3.9/site-packages/pip/_vendor/urllib3/response.py", line 527, in _fp_read
    return self._fp.read(amt) if amt is not None else self._fp.read()
  File "/root/.local/share/pypoetry/venv/lib/python3.9/site-packages/pip/_vendor/cachecontrol/filewrapper.py", line 90, in read
    data = self.__fp.read(amt)
  File "/usr/local/lib/python3.9/http/client.py", line 463, in read
    n = self.readinto(b)
  File "/usr/local/lib/python3.9/http/client.py", line 507, in readinto
    n = self.fp.readinto(b)
  File "/usr/local/lib/python3.9/socket.py", line 704, in readinto
    return self._sock.recv_into(b)
  File "/usr/local/lib/python3.9/ssl.py", line 1242, in recv_into
    return self.read(nbytes, buffer)
  File "/usr/local/lib/python3.9/ssl.py", line 1100, in read
    return self._sslobj.read(len, buffer)
socket.timeout: The read operation timed out

During handling of the above exception, another exception occurred:

Traceback (most recent call last):
  File "/root/.local/share/pypoetry/venv/lib/python3.9/site-packages/pip/_internal/cli/base_command.py", line 160, in exc_logging_wrapper
    status = run_func(*args)
  File "/root/.local/share/pypoetry/venv/lib/python3.9/site-packages/pip/_internal/cli/req_command.py", line 247, in wrapper
    return func(self, options, args)
  File "/root/.local/share/pypoetry/venv/lib/python3.9/site-packages/pip/_internal/commands/install.py", line 419, in run
    requirement_set = resolver.resolve(
  File "/root/.local/share/pypoetry/venv/lib/python3.9/site-packages/pip/_internal/resolution/resolvelib/resolver.py", line 92, in resolve
    result = self._result = resolver.resolve(
  File "/root/.local/share/pypoetry/venv/lib/python3.9/site-packages/pip/_vendor/resolvelib/resolvers.py", line 481, in resolve
    state = resolution.resolve(requirements, max_rounds=max_rounds)
  File "/root/.local/share/pypoetry/venv/lib/python3.9/site-packages/pip/_vendor/resolvelib/resolvers.py", line 348, in resolve
    self._add_to_criteria(self.state.criteria, r, parent=None)
  File "/root/.local/share/pypoetry/venv/lib/python3.9/site-packages/pip/_vendor/resolvelib/resolvers.py", line 172, in _add_to_criteria
    if not criterion.candidates:
  File "/root/.local/share/pypoetry/venv/lib/python3.9/site-packages/pip/_vendor/resolvelib/structs.py", line 151, in __bool__
    return bool(self._sequence)
  File "/root/.local/share/pypoetry/venv/lib/python3.9/site-packages/pip/_internal/resolution/resolvelib/found_candidates.py", line 155, in __bool__
    return any(self)
  File "/root/.local/share/pypoetry/venv/lib/python3.9/site-packages/pip/_internal/resolution/resolvelib/found_candidates.py", line 143, in <genexpr>
    return (c for c in iterator if id(c) not in self._incompatible_ids)
  File "/root/.local/share/pypoetry/venv/lib/python3.9/site-packages/pip/_internal/resolution/resolvelib/found_candidates.py", line 97, in _iter_built_with_inserted
    candidate = func()
  File "/root/.local/share/pypoetry/venv/lib/python3.9/site-packages/pip/_internal/resolution/resolvelib/factory.py", line 206, in _make_candidate_from_link
    self._link_candidate_cache[link] = LinkCandidate(
  File "/root/.local/share/pypoetry/venv/lib/python3.9/site-packages/pip/_internal/resolution/resolvelib/candidates.py", line 297, in __init__
    super().__init__(
  File "/root/.local/share/pypoetry/venv/lib/python3.9/site-packages/pip/_internal/resolution/resolvelib/candidates.py", line 162, in __init__
    self.dist = self._prepare()
  File "/root/.local/share/pypoetry/venv/lib/python3.9/site-packages/pip/_internal/resolution/resolvelib/candidates.py", line 231, in _prepare
    dist = self._prepare_distribution()
  File "/root/.local/share/pypoetry/venv/lib/python3.9/site-packages/pip/_internal/resolution/resolvelib/candidates.py", line 308, in _prepare_distribution
    return preparer.prepare_linked_requirement(self._ireq, parallel_builds=True)
  File "/root/.local/share/pypoetry/venv/lib/python3.9/site-packages/pip/_internal/operations/prepare.py", line 491, in prepare_linked_requirement
    return self._prepare_linked_requirement(req, parallel_builds)
  File "/root/.local/share/pypoetry/venv/lib/python3.9/site-packages/pip/_internal/operations/prepare.py", line 536, in _prepare_linked_requirement
    local_file = unpack_url(
  File "/root/.local/share/pypoetry/venv/lib/python3.9/site-packages/pip/_internal/operations/prepare.py", line 166, in unpack_url
    file = get_http_url(
  File "/root/.local/share/pypoetry/venv/lib/python3.9/site-packages/pip/_internal/operations/prepare.py", line 107, in get_http_url
    from_path, content_type = download(link, temp_dir.path)
  File "/root/.local/share/pypoetry/venv/lib/python3.9/site-packages/pip/_internal/network/download.py", line 147, in __call__
    for chunk in chunks:
  File "/root/.local/share/pypoetry/venv/lib/python3.9/site-packages/pip/_internal/cli/progress_bars.py", line 53, in _rich_progress_bar
    for chunk in iterable:
  File "/root/.local/share/pypoetry/venv/lib/python3.9/site-packages/pip/_internal/network/utils.py", line 63, in response_chunks
    for chunk in response.raw.stream(
  File "/root/.local/share/pypoetry/venv/lib/python3.9/site-packages/pip/_vendor/urllib3/response.py", line 622, in stream
    data = self.read(amt=amt, decode_content=decode_content)
  File "/root/.local/share/pypoetry/venv/lib/python3.9/site-packages/pip/_vendor/urllib3/response.py", line 587, in read
    raise IncompleteRead(self._fp_bytes_read, self.length_remaining)
  File "/usr/local/lib/python3.9/contextlib.py", line 137, in __exit__
    self.gen.throw(typ, value, traceback)
  File "/root/.local/share/pypoetry/venv/lib/python3.9/site-packages/pip/_vendor/urllib3/response.py", line 443, in _error_catcher
    raise ReadTimeoutError(self._pool, None, "Read timed out.")
pip._vendor.urllib3.exceptions.ReadTimeoutError: HTTPSConnectionPool(host='files.pythonhosted.org', port=443): Read timed out.

Traceback:

  File "<stdin>", line 923, in main
  File "<stdin>", line 560, in run
  File "<stdin>", line 581, in install
  File "/usr/local/lib/python3.9/contextlib.py", line 119, in __enter__
    return next(self.gen)
  File "<stdin>", line 653, in make_env
  File "<stdin>", line 639, in make_env
  File "<stdin>", line 352, in make
  File "<stdin>", line 375, in pip
  File "<stdin>", line 372, in python
  File "<stdin>", line 365, in run
